Workbook
Name Slicer_Month1: #N/A
Name Slicer_Sale_Date1: #N/A

Sheet Tasks
B1: Tasks & Questions
A2: 1 | B2: Calculate repayment rate (%) and average daily kWh usage for each cohort/month and compute overall portfolio repayment rate & average daily usage.
A3: 2 | B3: Segment cohorts/months into risk tiers (Low, Medium, High) using repayment percentage and average daily usage, and justify the thresholds.
A4: 3 | B4: Analyze arrears distribution across the portfolio and calculate the contribution percentage per cohort/month
A5: 4 | B5: Design a 2026 month-on-month dashboard for the field team, displaying sales, usage, repayment rate, arrears, and high-risk customers, including their arrears and contribution to overall portfolio arrears. Use charts and graphs to clearly present the data, and feel free to add any additional insights that may help
A6: 5 | B6: Propose three data-driven operational recommendations supported by quantitative findings, linking each recommendation to specific analytical insights.

Sheet Data
A1: Sale Date | B1: Month | C1: Customer Name | D1: Weekly Due (KES) | E1: Amount Paid (KES) | F1: ARREAS | G1: Rate of payment% | H1: Total kWh Used (Weekly) | I1: Active Days | J1: Risk customers
A2: 46054 | B2: =TEXT(A2,"mmm") -> Feb | C2: John Kiprotich | D2: 700 | E2: 8 | F2: =D2-E2 -> 692 | G2: =(E2/D2)*100 -> 1.1428571 | H2: 3.1 | I2: 2 | J2: =IF(AND(Data!F2>400, Data!G2<45), "HIGH", "NORMAL") -> HIGH
A3: 46053 | B3: =TEXT(A3,"mmm") -> Jan | C3: Diana Onyango | D3: 700 | E3: 18 | F3: =D3-E3 -> 682 | G3: =(E3/D3)*100 -> 2.5714286 | H3: 0 | I3: 0 | J3: =IF(AND(Data!F3>400, Data!G3<45), "HIGH", "NORMAL") -> HIGH
A4: 46069 | B4: =TEXT(A4,"mmm") -> Feb | C4: William Hassan | D4: 700 | E4: 34 | F4: =D4-E4 -> 666 | G4: =(E4/D4)*100 -> 4.8571429 | H4: 14.7 | I4: 7 | J4: =IF(AND(Data!F4>400, Data!G4<45), "HIGH", "NORMAL") -> HIGH
A5: 46023 | B5: =TEXT(A5,"mmm") -> Jan | C5: Mary Ochieng | D5: 700 | E5: 34 | F5: =D5-E5 -> 666 | G5: =(E5/D5)*100 -> 4.8571429 | H5: 7.7 | I5: 4 | J5: =IF(AND(Data!F5>400, Data!G5<45), "HIGH", "NORMAL") -> HIGH
A6: 46109 | B6: =TEXT(A6,"mmm") -> Mar | C6: Rose Njeri | D6: 700 | E6: 34 | F6: =D6-E6 -> 666 | G6: =(E6/D6)*100 -> 4.8571429 | H6: 0 | I6: 0 | J6: =IF(AND(Data!F6>400, Data!G6<45), "HIGH", "NORMAL") -> HIGH
A7: 46071 | B7: =TEXT(A7,"mmm") -> Feb | C7: Tabitha Said | D7: 700 | E7: 34 | F7: =D7-E7 -> 666 | G7: =(E7/D7)*100 -> 4.8571429 | H7: 1.7 | I7: 1 | J7: =IF(AND(Data!F7>400, Data!G7<45), "HIGH", "NORMAL") -> HIGH
A8: 46073 | B8: =TEXT(A8,"mmm") -> Feb | C8: Mercy Kiprotich | D8: 700 | E8: 45 | F8: =D8-E8 -> 655 | G8: =(E8/D8)*100 -> 6.4285714 | H8: 0 | I8: 0 | J8: =IF(AND(Data!F8>400, Data!G8<45), "HIGH", "NORMAL") -> HIGH
A9: 46064 | B9: =TEXT(A9,"mmm") -> Feb | C9: Alfred Abdallah | D9: 700 | E9: 57 | F9: =D9-E9 -> 643 | G9: =(E9/D9)*100 -> 8.1428571 | H9: 4.3 | I9: 2 | J9: =IF(AND(Data!F9>400, Data!G9<45), "HIGH", "NORMAL") -> HIGH
A10: 46072 | B10: =TEXT(A10,"mmm") -> Feb | C10: Joseph Chebet | D10: 700 | E10: 69 | F10: =D10-E10 -> 631 | G10: =(E10/D10)*100 -> 9.8571429 | H10: 3.2 | I10: 2 | J10: =IF(AND(Data!F10>400, Data!G10<45), "HIGH", "NORMAL") -> HIGH
A11: 46075 | B11: =TEXT(A11,"mmm") -> Feb | C11: James Mwende | D11: 700 | E11: 75 | F11: =D11-E11 -> 625 | G11: =(E11/D11)*100 -> 10.714286 | H11: 4 | I11: 2 | J11: =IF(AND(Data!F11>400, Data!G11<45), "HIGH", "NORMAL") -> HIGH
A12: 46061 | B12: =TEXT(A12,"mmm") -> Feb | C12: James Kimani | D12: 700 | E12: 78 | F12: =D12-E12 -> 622 | G12: =(E12/D12)*100 -> 11.142857 | H12: 2 | I12: 1 | J12: =IF(AND(Data!F12>400, Data!G12<45), "HIGH", "NORMAL") -> HIGH
A13: 46065 | B13: =TEXT(A13,"mmm") -> Feb | C13: Dennis Kariuki | D13: 700 | E13: 93 | F13: =D13-E13 -> 607 | G13: =(E13/D13)*100 -> 13.285714 | H13: 1.5 | I13: 1 | J13: =IF(AND(Data!F13>400, Data!G13<45), "HIGH", "NORMAL") -> HIGH
... A101: 46073 | B101: =TEXT(A101,"mmm") -> Feb | C101: Faith Mutiso | D101: 700 | E101: 700 | F101: =D101-E101 -> 0 | G101: =(E101/D101)*100 -> 100 | H101: 10.1 | I101: 6 | J101: =IF(AND(Data!F101>400, Data!G101<45), "HIGH", "NORMAL") -> NORMAL

Sheet PIVOT TABLES
A3: Months | B3: Average of Active Days | C3: Average of Rate of payment% | D3: Risk tires in payment
A4: Jan | B4: 4.6111111 | C4: 53.071429 | D4: =_xlfn.LET( _xlpm.val, GETPIVOTDATA("Average of Rate of payment%", $A$3, "Month", "Jan"), IF(_xlpm.val > 65, "LOW RISK", IF(AND(_xlpm.val >= 50, _xlpm.val < 65), "Medium", "HIGH") ) ) -> Medium
A5: Feb | B5: 4.3396226 | C5: 52.345013 | D5: =_xlfn.LET( _xlpm.val, GETPIVOTDATA("Average of Rate of payment%", $A$3, "Month", "Feb"), IF(_xlpm.val > 65, "LOW RISK", IF(AND(_xlpm.val >= 50, _xlpm.val < 65), "Medium", "HIGH") ) ) -> Medium
A6: Mar | B6: 3.3448276 | C6: 65.192118 | D6: =_xlfn.LET( _xlpm.val, GETPIVOTDATA("Average of Rate of payment%", $A$3, "Month", "Mar"), IF(_xlpm.val > 65, "LOW RISK", IF(AND(_xlpm.val >= 50, _xlpm.val < 65), "Medium", "HIGH") ) ) -> LOW RISK
A7: (blank)
B10: Arreas across the Months
A12: Months | B12: Sum of Amount Paid (KES) | C12: Sum of ARREAS | D12: Sum of Weekly Due (KES) | E12: Average of Rate of payment% | F12: Average of Total kWh Used (Weekly) | G12: Sum of Active Days
A13: Feb | B13: 19420 | C13: 17680 | D13: 37100 | E13: 52.345013 | F13: 8.2528302 | G13: 230
A14: Mar | B14: 13234 | C14: 7066 | D14: 20300 | E14: 65.192118 | F14: 6.2448276 | G14: 97
A15: (blank)
A16: Grand Total | B16: 32654 | C16: 24746 | D16: 57400 | E16: 56.888502 | F16: 7.5426829 | G16: 327
A19: Row Labels | B19: Average of Rate of payment% | C19: Average of Total kWh Used (Weekly) | D19: Sum of Active Days
A20: Jan | B20: 53.071429 | C20: 9.05 | D20: 83
A21: Feb | B21: 52.345013 | C21: 8.2528302 | D21: 230
A22: Mar | B22: 65.192118 | C22: 6.2448276 | D22: 97
A23: Grand Total | B23: 56.201429 | C23: 7.814 | D23: 410
A26: Row Labels | B26: Sum of Amount Paid (KES) | C26: Sum of ARREAS
A27: Faith Mutiso | B27: 1400 | C27: 0
A28: Leah Onyango | B28: 1214 | C28: 186
A29: Victor Hassan | B29: 1115 | C29: 285
A30: Rose Said | B30: 828 | C30: 572
A31: Irene Mutiso | B31: 700 | C31: 0
A32: Lydia Wanjiku | B32: 650 | C32: 50
A33: Nancy Chebet | B33: 650 | C33: 50
A34: James Kariuki | B34: 650 | C34: 50
A35: Henry Abdallah | B35: 649 | C35: 51
A36: Jacob Atieno | B36: 649 | C36: 51
A37: Asha Otieno | B37: 647 | C37: 53
A38: Peter Naliaka | B38: 647 | C38: 53 | E38: Months | F38: Count of Customer Name
A39: William Ochieng | B39: 647 | C39: 53 | E39: Jan | F39: 18
A40: Victor Kiprotich | B40: 612 | C40: 88 | E40: Feb | F40: 53
A41: Samuel Abdallah | B41: 609 | C41: 91 | E41: Mar | F41: 29
A42: Henry Mussa | B42: 609 | C42: 91 | E42: Grand Total | F42: 100
A43: Victor Onyango | B43: 609 | C43: 91
A44: Kelvin Mutiso | B44: 609 | C44: 91
A45: Caroline Wairimu | B45: 609 | C45: 91
A46: Lydia Atieno | B46: 609 | C46: 91
A47: Fatma Odhiambo | B47: 593 | C47: 107
A48: Mary Ochieng | B48: 592 | C48: 808
A49: Irene Ochieng | B49: 565 | C49: 135
...

Sheet Dashbord
C5: =GETPIVOTDATA("Sum of Amount Paid (KES)",'PIVOT TABLES'!$A$12) -> 32654 | G5: =GETPIVOTDATA("Sum of ARREAS",'PIVOT TABLES'!$A$12) -> 24746 | J5: =GETPIVOTDATA("Average of Rate of payment%",'PIVOT TABLES'!$A$12) -> 56.888502 | M5: =GETPIVOTDATA("Average of Total kWh Used (Weekly)",'PIVOT TABLES'!$A$12) -> 7.5426829 | O5: =GETPIVOTDATA("Sum of Active Days",'PIVOT TABLES'!$A$12) -> 327
B22: Names | C22: Sum of Amount Paid (KES) | D22: Sum of ARREAS (KES)
B23: Faith Mutiso | C23: 1400 | D23: 0 | G23: Row Labels | H23: Sum of Active Days | I23: Average of Total kWh Used (Weekly)
B24: Leah Onyango | C24: 1214 | D24: 186 | G24: Leah Onyango | H24: 13 | I24: 11.65
B25: Victor Hassan | C25: 1115 | D25: 285 | G25: Faith Mutiso | H25: 13 | I25: 10.65
B26: Rose Said | C26: 828 | D26: 572 | G26: Rose Said | H26: 11 | I26: 8.95
B27: Irene Mutiso | C27: 700 | D27: 0 | G27: Mary Ochieng | H27: 9 | I27: 8.3
B28: Lydia Wanjiku | C28: 650 | D28: 50 | G28: Stephen Mussa | H28: 7 | I28: 15.5
B29: Nancy Chebet | C29: 650 | D29: 50 | G29: Peter Naliaka | H29: 7 | I29: 15.8
B30: James Kariuki | C30: 650 | D30: 50 | G30: Nancy Onyango | H30: 7 | I30: 14.3
B31: Henry Abdallah | C31: 649 | D31: 51 | G31: Diana Mwangi | H31: 7 | I31: 10.8
B32: Jacob Atieno | C32: 649 | D32: 51 | G32: Salma Atieno | H32: 7 | I32: 12.1
B33: Asha Otieno | C33: 647 | D33: 53 | G33: Asha Otieno | H33: 7 | I33: 15
B34: Peter Naliaka | C34: 647 | D34: 53 | G34: Victor Hassan | H34: 7 | I34: 6.65
B35: William Ochieng | C35: 647 | D35: 53 | G35: Fatma Joseph | H35: 7 | I35: 15.3
... B117: John Kiprotich | C117: 8 | D117: 692 | G117: Alfred Njoroge | H117: 0 | I117: 0
G118: Rose Njeri | H118: 0 | I118: 0
